Workbook

Sheet Collections_v2
A1: COL-id | B1: rang | C1: nom | D1: slogan | E1: description | F1: couleur_hex | G1: photo_url | H1: photo_noel_url
A2: COL-001 | B2: 1 | C2: SAPONICA | D2: Simplement la nature qui prend soin de vous | E2: SAPONICA, c'est le savon dans sa forme la plus pure. Huile de tournesol, huile de coco, beurre de karité — une base généreuse, soigneusement surgraissée, qui nettoie sans jamais décaper. Sa mousse crémeuse enveloppe, sa glycérine naturelle hydrate, et votre peau ressort douce, sans avoir besoin de rien d'autre. Sur cette base, chaque savon devient une histoire. Boréal sent la forêt boréale et ses grands espaces. Délicat murmure la pivoine et la lavande. Étreinte gourmande réunit l'avoine, le miel et l'amande. D'un savon à l'autre, la même âme — des personnalités radicalement différentes. | F2: #8A7A4A | G2: https://res.cloudinary.com/dfasrauyy/image/upload/v1773699699/saponica_yvg3if.jpg
A3: COL-002 | B3: 2 | C3: PETIT NUAGE | D3: Simplement la nature qui dorlote vos tout-petits | E3: La peau des tout-petits mérite ce qu'il y a de plus doux. PETIT NUAGE est formulé sans compromis pour les épidermes les plus fragiles — surgraissé à 10%, avec des ingrédients choisis un à un pour leur douceur. Un savon qui prend soin sans jamais irriter. Câlin sent la poudre de bébé, Fleuri évoque un matin de printemps, Rosé murmure la tendresse quotidienne. Chaque savon a sa douceur, sa couleur, son caractère — tous pensés pour les peaux les plus précieuses. | F3: #E8D8E0 | G3: https://res.cloudinary.com/dfasrauyy/image/upload/v1773699700/nuage_tn6a3j.jpg
A4: COL-003 | B4: 3 | C4: CAPRIN | D4: Simplement la nature et la douceur de la chèvre | E4: Le lait de chèvre, c'est une douceur qu'on reconnaît au premier contact. Riche en vitamines et en acides gras, il nourrit, apaise, respecte même les peaux les plus réactives. Dans chaque savon CAPRIN, il s'unit aux huiles végétales et au beurre de karité pour une mousse crémeuse, lactée, qui prend soin sans jamais agresser. Pomme verte, melon d'eau, cerise — CAPRIN joue avec les fraîcheurs fruitées sur cette base douce et constante. Des savons qui sentent bon, qui font du bien, et qui donnent envie de recommencer. | F4: #957A6A | G4: https://res.cloudinary.com/dfasrauyy/image/upload/v1773699700/Caprin_wbqg5n.jpg
A5: COL-004 | B5: 4 | C5: ÉMOLIA | D5: Simplement la nature dédiée à votre bien-être | E5: ÉMOLIA, c'est la collection pour ceux qui prennent soin d'eux avec intention. Pas juste se laver — se choyer. Des baumes qui réparent, des bombes de bain qui transforment le bain en rituel, des soins qui restent sur la peau longtemps après le rinçage. L'essentiel du bien-être, pensé avec la même philosophie que nos savons. Des lèvres aux talons, ÉMOLIA couvre tout. Baumes à lèvres nourrissants, bombes de bain effervescentes, baumes corporels enveloppants, savon exfoliant revitalisant. Chaque produit est une invitation à ralentir, à s'offrir un moment rien qu'à soi. | F5: #C4956A | G5: https://res.cloudinary.com/dfasrauyy/image/upload/v1774629279/a-minimalist-still-life-photograph-featu_OmMoSBO5T2WkphsZCBhDQA_DSW-Hw_cTSqI_Is56u75Dg_aesvzs.jpg | H5: https://res.cloudinary.com/dfasrauyy/image/upload/v1774629280/a-serene-still-life-photograph-showcasin_RGQ_K97WRBix5vsk004MBg_XyOEAMnuTrO2d-vs37jRYg_vl9eo0.jpg
A6: COL-005 | B6: 5 | C6: ÉPURE | D6: Simplement la nature entre vos mains | E6: ÉPURE, c'est le savon qu'on garde près de l'évier. Cubique, solide, sans fioritures — mais pas sans soin. Formulé pour les mains qui travaillent, cuisinent, jardinent, bricolent. Il nettoie en profondeur, décroche la graisse, et laisse les mains douces sans avoir besoin de crème après. Grain d'acier pour les mains marquées d'huile et de métal. Mousse d'espresso pour réveiller les sens au café du matin. Herbe douce pour la fraîcheur du jardin. Murmure d'Oliva pour un souffle méditerranéen près du fourneau. Chacun a son caractère — tous ont la même solidité. | F6: #6A6A50 | G6: https://res.cloudinary.com/dfasrauyy/image/upload/v1773699700/epure_tvqlz0.jpg
A7: COL-006 | B7: 6 | C7: KÉRYS | D7: Simplement la nature qui veille sur vos cheveux | E7: KÉRYS, c'est le soin capillaire repensé en barre. Concentré, efficace, sans eau inutile — il lave, nourrit et respecte le cuir chevelu en un seul geste. Pas de compromis sur les ingrédients, pas de contenant plastique à jeter. Juste ce qu'il faut, là où ça compte. Trois lignes, trois natures de cheveux. PURÉLIA pour les cheveux gras qui cherchent la légèreté. ÉQUILIBRA pour les cheveux normaux qui veulent rester équilibrés. HYDRABOUCLE pour les boucles qui réclament hydratation et définition. Chaque ligne a ses formules, ses ingrédients, sa promesse. | F7: #5A9A7A | G7: https://res.cloudinary.com/dfasrauyy/image/upload/v1773699700/kerys_tan8yy.jpg
A8: COL-007 | B8: 7 | C8: CASA | D8: Simplement la nature pour votre maison | E8: CASA, c'est la même philosophie que pour votre peau — appliquée à votre maison. Des produits pensés avec les mêmes exigences : ingrédients choisis, efficacité réelle, sans compromis. Parce que prendre soin de son intérieur, c'est aussi prendre soin de soi. Un cake vaisselle qui dégraisse sans agresser les mains. Une bruine d'ambiance qui transforme l'air en un souffle parfumé. Une eau de linge qui dépose une douceur discrète sur chaque fibre. Le quotidien, sublimé. | F8: #9AAF60 | G8: https://res.cloudinary.com/dfasrauyy/image/upload/v1774629280/a-serene-still-life-photograph-capturing_eNdcu-T-QwOlCQFoxMnZoA_QGE0w6WwRdKH6816Kjky-w_oxu2k1.jpg
A9: COL-008 | B9: 8 | C9: LUI | D9: Simplement la nature au masculin | E9: Prendre soin de soi n'est pas une question de genre, mais d'exigence. LUI rassemble des produits pensés pour les hommes qui choisissent le naturel sans sacrifier l'efficacité. Les mêmes ingrédients, le même soin artisanal — avec des parfums boisés, frais, affirmés. Savons pour le corps et les mains, huile à barbe nourrissante, savon à raser en développement. Cèdre bleu, patchouli, bois de santal, romarin — des parfums qui parlent d'eux-mêmes. | F9: #3A5A6A | G9: https://res.cloudinary.com/dfasrauyy/image/upload/v1773716071/IMG_3026_gngdtk.jpg
A10: COL-009 | B10: 9 | C10: ANIMA | D10: Simplement la nature pour pattes et museaux | E10: Nos compagnons méritent le même soin que nous. ANIMA est formulé avec la même rigueur que nos savons pour la peau humaine — saponifié à froid, surgraissé, avec des ingrédients choisis pour leurs bienfaits. Argile purifiante, avoine apaisante, sans huiles essentielles ni parfum ajouté. Parce que l'odorat d'un chien ou d'un chat est bien trop précieux pour être brusqué. Pattes blanches, le seul et unique pour l'instant — mais pensé avec autant d'attention que toute la gamme. Un bain qui nettoie en douceur, respecte la peau sous le pelage, et laisse votre compagnon propre sans l'incommoder. | F10: #C4845A | G10: https://res.cloudinary.com/dfasrauyy/image/upload/v1773699700/Anima_iacrow.jpg

Sheet Gammes_v2
A1: GAM-id | B1: COL-id | C1: rang | D1: nom | E1: description | F1: couleur_hex | G1: photo_url | H1: photo_noel_url
A2: GAM-001 | B2: COL-001 | C2: 1 | D2: SAVON
A3: GAM-002 | B3: COL-002 | C3: 1 | D3: SAVON
A4: GAM-003 | B4: COL-003 | C4: 1 | D4: SAVON AU LAIT DE CHÈVRE
A5: GAM-004 | B5: COL-004 | C5: 1 | D5: BAUME
A6: GAM-005 | B6: COL-004 | C6: 2 | D6: BOMBES DE BAIN | E6: Une boule, un plongeon, et le bain se transforme. L'effervescence du bicarbonate, le sel d'Epsom qui détend les muscles, l'huile d'amande qui soyeuse la peau — tout ça en un seul geste. Un rituel simple qui fait toute la différence. Même magie, formule adaptée aux tout-petits. Sans sel d'Epsom, sans huiles essentielles — juste l'effervescence joyeuse et la douceur de l'amande et du karité. Le bain devient une fête.
A7: GAM-006 | B7: COL-004 | C7: 3 | D7: BAUME À LÈVRES | E7: Une caresse nourrissante qui protège et répare. L'huile de noix de coco hydrate en profondeur, la cire d'abeille crée un voile protecteur, la vitamine E préserve, tandis que le beurre de mangue apporte une douceur veloutée. Des lèvres douces, naturellement sublimées.
A8: GAM-007 | B8: COL-004 | C8: 4 | D8: SAVON
A9: GAM-008 | B9: COL-004 | C9: 5 | D9: SAVON EXFOLIANT
A10: GAM-009 | B10: COL-005 | C10: 1 | D10: SAVON À MAIN
A11: GAM-010 | B11: COL-006 | C11: 1 | D11: ÉQUILIBRA | E11: L'équilibre au quotidien. Des formules douces qui respectent le cuir chevelu naturellement bien réglé — pour qu'il le reste, lavage après lavage.
A12: GAM-011 | B12: COL-006 | C12: 2 | D12: PURÉLIA | E12: La source limpide où les cheveux retrouvent leur légèreté. Argiles absorbantes et ingrédients purifiants dissolvent l'excès sans décaper, sans alourdir. Le cuir chevelu respire, les cheveux brillent.
A13: GAM-012 | B13: COL-006 | C13: 3 | D13: HYDRABOUCLE | E13: Les boucles ont leurs propres besoins. HYDRABOUCLE les nourrit, les hydrate, les enlace d'une douceur protectrice — sans jamais les alourdir ni les dompter.
A14: GAM-013 | B14: COL-007 | C14: 1 | D14: BRUINE D'AMBIANCE | E14: L'atmosphère en bouteille. Ce spray délicat transforme instantanément l'air de votre intérieur en une invitation à la détente. Formulée à base d'eau distillée et de fragrances naturelles, la bruine d'ambiance enveloppe chaque pièce d'un voile olfactif subtil et éphémère. Une impulsion, et l'espace se métamorphose.
A15: GAM-014 | B15: COL-007 | C15: 2 | D15: CAKE VAISSELLE | E15: Dans la continuité de notre collection de savons pour les mains, Épure Vaisselle apporte la même philosophie d'authenticité à l'évier. Un pain solide qui mousse généreusement au contact de l'eau et de l'éponge. Son pouvoir dégraissant naturel ce savon vaisselle fait disparaître les résidus alimentaires sans laisser de traces. Sa texture ferme et compacte lui confère une longévité exceptionnelle : un seul pain remplace plusieurs flacons de liquide vaisselle.
A16: GAM-015 | B16: COL-007 | C16: 3 | D16: EAU DE LINGE | E16: Le linge comme une seconde peau. Vaporisée sur vos tissus avant ou après le repassage, cette eau délicatement parfumée prolonge la fraîcheur et laisse sur draps, vêtements et linges de maison un sillage doux et naturel. Parce que la douceur commence dès le matin, au contact du tissu.
A17: GAM-016 | B17: COL-007 | C17: 4 | D17: BOUGIE | E17: LUMINA, c'est l'atmosphère en cire. Des chandelles artisanales à base de cire de soya qui brûlent doucement, proprement, longtemps. La flamme danse, le parfum s'installe, la pièce se transforme. Lessive fraîche, Pivoine et Poire — des fragrances exclusives aux chandelles, disponibles en tout temps. Club privé, Feu d'automne, Nuage de lavande de SAPONICA, disponibles régulièrement.
A18: GAM-017 | B18: COL-008 | C18: 1 | D18: SAVAGE SAVONNERIE
A19: GAM-018 | B19: COL-008 | C19: 2 | D19: SAVON À RASER
A20: GAM-019 | B20: COL-009 | C20: 1 | D20: SAVON
A21: GAM-1775511367298 | B21: COL-008 | C21: 1 | D21: HUILE À BARBE
A22: GAM-1775518159265 | B22: COL-007 | C22: 5 | D22: SAVON DU PAYS

Sheet Familles_v2
A1: FAM-id | B1: COL-id | C1: rang | D1: nom | E1: description | F1: couleur_hex | G1: photo_url | H1: photo_noel_url
A2: FAM-001 | B2: COL-008 | C2: 1 | D2: BARBE ET MOUSTACHE | E2: Tout pour votre visage
A3: FAM-1775511526523 | B3: COL-008 | C3: 2 | D3: SÉRIE - EN COLLABORATION | E3: Pour vous faire découvrir d’autres artisans
A4: FAM-1775732950384 | B4: COL-004 | C4: 1 | D4: BAUME HIVER | E4: Pour affronter le froid et la sécheresse

Sheet Produits_v2
A1: PRO-id | B1: COL-id | C1: GAM-id | D1: FAM-id | E1: nom | F1: description | G1: desc_emballage | H1: couleur_hex | I1: surgras | J1: nb_unites | K1: cure | L1: instructions | M1: notes | N1: image_url | O1: image_noel_url | P1: statut | Q1: collections_secondaires
A2: PRO-014 | B2: COL-001 | C2: GAM-001 | E2: BRISE DES LAGUNES | F2: Il y a des endroits qu'on ne visite qu'en rêve. Brise des lagunes capture cet instant suspendu. L'argile blanche purifie en douceur tandis que la brise marine et le cèdre bleu s'enlacent dans une mousse soyeuse. | G2: La fraîcheur des eaux secrètes, la caresse des vents marins. | H2: #3EAF85 | I2: 0.08 | J2: 9 | K2: 28 | M2: Huile aromatique Jasmin, Huile aromatique Lotus, HE Christe marine, Huile aromatique Bois de santal, HE Romarin, HE Bois de Hô, HE Citron / ½ sarcelle, ½ Argile blanche | N2: https://res.cloudinary.com/dfasrauyy/image/upload/v1773418760/Brisedeslagunes_nurrcu.jpg | O2: https://res.cloudinary.com/dfasrauyy/image/upload/v1773418760/BrisedeslagunesNoel_whufa1.jpg | P2: public | Q2: COL-008
A3: PRO-041 | B3: COL-001 | C3: GAM-001 | E3: ÉCLAT FLORAL | F3: Éclat floral célèbre la beauté simple et lumineuse du naturel. L'Argile Multani mutti illumine, les confettis de fleurs couronnent chaque barre d'une touche unique et poétique. | G3: Un savon mosaïque, doré d'Argile jaune et parsemé de fleurs, où chaque fragment renaît en douceur. | H3: #FFB400 | I3: 0.08 | J3: 9 | K3: 28 | M3: 17.5g Argile Multani mutti = 5 c. à thé / Fleurs confettis sur le dessus | N3: https://res.cloudinary.com/dfasrauyy/image/upload/v1773448829/Eclatfloral_rqh0ry.jpg | O3: https://res.cloudinary.com/dfasrauyy/image/upload/v1773448784/Eclatfloralnoel_om51gw.jpg | P3: public
A4: PRO-042 | B4: COL-001 | C4: GAM-001 | E4: ÉCLAT TROPICAL | F4: Ferme les yeux et laisse la mandarine, l'orange douce et la pêche t'emporter quelque part entre un marché tropical et un verger en plein soleil. | G4: Mangue, pêche, mandarine. Un été qui ne finit jamais. | H4: #FF6735 | I4: 0.08 | J4: 9 | K4: 28 | M4: 10.5g Argile blanche = 3 c. à thé / Restes de savon coco-mangue en petits morceaux | N4: https://res.cloudinary.com/dfasrauyy/image/upload/v1773448785/Eclatfloral_lg1ysi.jpg | O4: https://res.cloudinary.com/dfasrauyy/image/upload/v1773448370/Eclattropicalnoel_iggl8h.jpg | P4: public
A5: PRO-053 | B5: COL-001 | C5: GAM-001 | E5: JARDIN D'AURORE | F5: Le concombre frais du potager s'unit à la menthe qui borde les allées, comme un hommage aux mains qui ont cultivé ces merveilles. | G5: Fraîcheur de concombre, souffle de menthe, un jardin qui respire entre les mains. | H5: #65791A | I5: 0.08 | J5: 9 | K5: 28 | M5: Un p'tit clin d'œil à ma grand-mère que j'aurais voulu connaître. | N5: https://res.cloudinary.com/dfasrauyy/image/upload/v1773449232/Jardindaurore_vtpqvp.jpg | O5: https://res.cloudinary.com/dfasrauyy/image/upload/v1773449232/Jardindaurorenoel_vitnor.jpg | P5: public
A6: PRO-073 | B6: COL-001 | C6: GAM-001 | E6: SOLEIL DE PROVENCE | F6: Le citron et les agrumes éclatent sous le soleil, le romarin sauvage pousse entre les pierres chaudes. Soleil de Provence capture cette simplicité lumineuse. | G6: Agrumes et romarin sauvage. Le sud de la France dans chaque mousse. | H6: #FD791A | I6: 0.08 | J6: 9 | K6: 28 | M6: Orange | N6: https://res.cloudinary.com/dfasrauyy/image/upload/v1773448369/Soleildeprovence_pue3as.jpg | O6: https://res.cloudinary.com/dfasrauyy/image/upload/v1773448369/Soleildeprovencenoel_hbh9lb.jpg | P6: public
A7: PRO-078 | B7: COL-001 | C7: GAM-001 | E7: VOILE DE POIRE | F7: Il y a des savons tout en légèreté. La poire juteuse ouvre le bal, le thé vert apporte sa subtilité végétale, la bergamote signe d'une touche florale et citronnée. | G7: Poire juteuse, thé vert, bergamote. Une douceur qui glisse. | H7: #91D129 | I7: 0.08 | J7: 9 | K7: 28 | M7: Vert kiwi / 11g Argile blanche = 1 c. à table | N7: https://res.cloudinary.com/dfasrauyy/image/upload/v1773448369/Voiledepoire_ue6ufc.jpg | O7: https://res.cloudinary.com/dfasrauyy/image/upload/v1773448370/Voiledepoirenoel_xg6jef.jpg | P7: public
A8: PRO-066 | B8: COL-002 | C8: GAM-002 | E8: PETIT NUAGE CÂLIN | F8: Sa mousse légère rappelle le parfum délicat du linge frais, une senteur poudrée qui apaise et réconforte. | G8: Un savon tendre comme une étreinte, pensé pour envelopper la peau d'une douceur rassurante. | H8: #B7DCC4 | I8: 0.1 | J8: 9 | K8: 28 | M8: 1 c. à thé argile blanche ou rose = 5g | N8: https://res.cloudinary.com/dfasrauyy/image/upload/v1773083346/univers-caresse/produits/vw5bdqa4j1dumkwjodzr.jpg | P8: public
A9: PRO-067 | B9: COL-002 | C9: GAM-002 | E9: PETIT NUAGE DOUCE BAIE | F9: Un savon tendre et fruité, comme une caresse mauve venue des sous-bois. Sa mousse délicate s'imprègne de la douceur des mûres. | G9: Un souffle mauve et fruité, velouté comme un smoothie d'été, doux comme une caresse de mûre. | H9: #5A4657 | I9: 0.1 | J9: 9 | K9: 28 | M9: 1 c. à thé argile blanche ou rose = 5g | N9: https://res.cloudinary.com/dfasrauyy/image/upload/v1773083394/univers-caresse/produits/gncwgz5xektcburqtpzr.jpg | P9: public
A10: PRO-068 | B10: COL-002 | C10: GAM-002 | E10: PETIT NUAGE FLEURI | F10: Sa mousse douce s'imprègne de la fraîcheur du pois de senteur, une odeur naturelle, légère et florale qui évoque les bouquets d'enfance. | G10: Un savon lumineux et joyeux, comme un matin de printemps. | H10: #F8E7A1 | I10: 0.1 | J10: 9 | K10: 28 | M10: 1 c. à thé argile blanche ou rose = 5g | N10: https://res.cloudinary.com/dfasrauyy/image/upload/v1773083428/univers-caresse/produits/qiea1clad0wsqu8x4v1r.jpg | P10: public
A11: PRO-069 | B11: COL-002 | C11: GAM-002 | E11: PETIT NUAGE ROSÉ | F11: Un voile tendre et aérien, comme une caresse de l'aube. La douceur de l'huile végétale amande douce et du karité se marie à la légèreté de l'olive. | G11: Une bulle de tendresse, une invitation à la douceur quotidienne. | H11: #F7DDE6 | I11: 0.1 | J11: 9 | K11: 28 | M11: 1 c. à thé argile blanche ou rose = 5g | N11: https://res.cloudinary.com/dfasrauyy/image/upload/v1773083525/univers-caresse/produits/kdrgqwki1vaclkhjln4c.jpg | P11: public
A12: PRO-028 | B12: COL-003 | C12: GAM-003 | E12: CAPRICE FRAISÉ | F12: Le lait de chèvre enveloppe, la fraise éveille. Un savon gourmand qui prend soin de la peau avec une douceur crémeuse et un parfum fruité irrésistible. | G12: L'alliance gourmande du lait onctueux et de la fraise sucrée. | H12: #A2414D | I12: 0.08 | J12: 12 | K12: 42 | M12: Utiliser de l'eau glacée pour ralentir la réaction avec le lait de chèvre. | P12: public
A13: PRO-029 | B13: COL-003 | C13: GAM-003 | E13: CERISE DE VELOURS | F13: La cerise, juteuse et sucrée, apporte sa douceur fruitée à une mousse crémeuse et veloutée. Dans ce savon au lait de chèvre, elle s'unit à l'argile blanche purifiante. | G13: Savon gourmand au lait de chèvre et cerises, douceur fruitée et peau satinée. | H13: #BF0E24 | I13: 0.08 | J13: 12 | K13: 42 | M13: Utiliser de l'eau glacée pour ralentir la réaction avec le lait de chèvre. | P13: public
A14: PRO-043 | B14: COL-003 | C14: GAM-003 | E14: ÉCLOSION DE SOIE | F14: La spiruline apporte sa richesse végétale, le jasmin envoûte, le thé vert protège. Éclosion de soie est un savon au lait de chèvre qui prend soin de la peau avec une douceur florale et végétale. | G14: Un savon velouté où le jasmin s'ouvre doucement sur un fond de thé vert et de lait crémeux. Une caresse soyeuse, presque textile. | H14: #476B33 | I14: 0.08 | J14: 12 | K14: 42 | M14: Utiliser de l'eau glacée pour ralentir la réaction avec le lait de chèvre. | P14: public
A15: PRO-049 | B15: COL-003 | C15: GAM-003 | E15: FRAÎCHEUR DE MELON | F15: Le melon d'eau apporte sa légèreté aquatique et sucrée à la richesse crémeuse du lait de chèvre. | G15: La douceur crémeuse du lait de chèvre épouse la légèreté rafraîchissante du melon d'eau. | H15: #BF705E | I15: 0.08 | J15: 12 | K15: 42 | M15: Utiliser de l'eau glacée pour ralentir la réaction avec le lait de chèvre. | P15: public
A16: PRO-062 | B16: COL-003 | C16: GAM-003 | E16: ORANGE SAUVAGE | F16: L'orange douce s'embrase au contact de la cannelle, du gingembre et du clou de girofle. Le curcuma illumine, l'écorce d'orange texturise légèrement. | G16: Éclat d'agrume et souffle d'épices, comme une chaleur libre qui danse sur la peau. | H16: #C67D26 | I16: 0.08 | J16: 12 | K16: 42 | M16: Utiliser de l'eau glacée pour ralentir la réaction avec le lait de chèvre. | P16: public
A17: PRO-070 | B17: COL-003 | C17: GAM-003 | E17: POMME D'ÉMERAUDE | F17: La pomme verte apporte sa fraîcheur acidulée et légère à la douceur crémeuse du lait de chèvre. Le mica vert illumine chaque barre d'un éclat naturel. | G17: Savon délicat au lait de chèvre et pomme verte, fraîcheur et douceur en un seul geste. | H17: #51EB4E | I17: 0.08 | J17: 12 | K17: 42 | M17: Utiliser de l'eau glacée pour ralentir la réaction avec le lait de chèvre. | P17: public
A18: PRO-044 | B18: COL-004 | C18: GAM-004 | E18: EFFLUVE APAISANT | F18: Un souffle clair qui libère la respiration, une chaleur douce qui réconforte. Effluve apaisant dépose sur la peau un nuage aromatique qui apaise l'hiver. | G18: Un baume aromatique qui dégage, réchauffe et réconforte — le souffle de l'hiver apprivoisé. | H18: #E7B539 | I18: 0 | J18: 1 | K18: 0 | M18: **Version courte :** Un baume aromatique qui dégage, réchauffe et réconforte — le souffle de l'hiver apprivoisé. | P18: public
A19: PRO-064 | B19: COL-004 | C19: GAM-004 | E19: PETIT BOUCLIER | F19: Un voile de douceur qui enveloppe la peau d'un confort rassurant, comme un nuage qui veille. Pour les petits bobos du quotidien. | G19: Un voile protecteur tout en douceur, pour les petites peaux qui ont besoin d'être chouchoutées. | H19: #519A9C | I19: 0 | J19: 1 | K19: 0 | M19: Les zones comme les fesses sont plus sensibles / Pour utilisation externe seulement | P19: public
A20: PRO-006 | B20: COL-004 | C20: GAM-005 | E20: BOMBE BAIN BRISE DES LAGUNES | F20: Laissez l'effervescence dessiner des lagunes dans votre bain. Brise des lagunes capture l'air salin des eaux turquoise, le souffle tiède du cèdre bleu qui s'attarde sur la peau. | G20: Une escapade aquatique — la brise marine et le cèdre bleu pour un bain qui sent l'horizon. | H20: #3EAF85 | I20: 0 | J20: 3 | K20: 0 | M20: 10g Eau = 2 c. à thé / 45g Huile végétale amande douce = 3 c. à table / 6g fleurs = 1 c. à table / Colorant ⚠️ à confirmer avec Chantal / 6g fleurs si désiré | P20: public
A21: PRO-007 | B21: COL-004 | C21: GAM-005 | E21: BOMBE BAIN DÉLICAT | F21: Délicat invite la pivoine et la lavande à danser dans votre bain. L'effervescence libère un voile floral subtil et apaisant. | G21: Pivoine, lavande et thé vert — une effervescence florale toute en douceur. | H21: #AF99A4 | I21: 0 | J21: 3 | K21: 0 | M21: 10g Eau = 2 c. à thé / 45g Huile végétale amande douce = 3 c. à table / 6g fleurs = 1 c. à table / Colorant ⚠️ à confirmer avec Chantal / 6g fleurs si désiré | P21: public
A22: PRO-008 | B22: COL-004 | C22: GAM-005 | E22: BOMBE BAIN DOUCE PENSÉE | F22: Douce pensée transforme le bain en un rituel floral et sensuel. Le géranium rosat équilibre, l'ylang-ylang enveloppe d'une chaleur presque tropicale. | G22: Géranium rosat et ylang-ylang — une effervescence florale chaude et enveloppante. | H22: #E76877 | I22: 0 | J22: 3 | K22: 0 | M22: 10g Eau = 2 c. à thé / 45g Huile végétale amande douce = 3 c. à table / 6g fleurs = 1 c. à table / Colorant ⚠️ à confirmer avec Chantal / 6g fleurs si désiré | P22: public
A23: PRO-009 | B23: COL-004 | C23: GAM-005 | E23: BOMBE BAIN NUAGE DE LAVANDE | F23: Nuage de lavande n'a pas besoin de complices. La lavande se déploie dans l'effervescence, enveloppe le bain d'un voile apaisant et profond. | G23: La lavande à l'état pur — une effervescence douce pour un bain tout en quiétude. | H23: #7F68CA | I23: 0 | J23: 3 | K23: 0 | M23: 10g Eau = 2 c. à thé / 45g Huile végétale amande douce = 3 c. à table / 6g fleurs = 1 c. à table / Colorant ⚠️ à confirmer avec Chantal / 6g fleurs si désiré | P23: public
A24: PRO-010 | B24: COL-004 | C24: GAM-005 | E24: BOMBE BAIN VANILLE ET CITRON | F24: Vanille et citron, c'est le duo inattendu qui réchauffe et éveille à la fois. | G24: La douceur de la vanille rencontre le pétillement du citron — un bain gourmand et lumineux. | H24: #FFF8DC | I24: 0 | J24: 3 | K24: 0 | M24: 10g Eau = 2 c. à thé / 45g Huile végétale amande douce = 3 c. à table / 6g fleurs = 1 c. à table / Colorant ⚠️ à confirmer avec Chantal / arôme de vanille à confirmer avec Chantal | P24: public
A25: PRO-011 | B25: COL-004 | C25: GAM-005 | E25: BOMBES DE BAIN PETIT NUAGE | F25: L'heure du bain devient une fête. Ces bombes douces et colorées transforment l'eau en une bulle de tendresse parfumée. Sans huile essentielle, sans sel d'Epsom. | I25: 0 | J25: 24 | K25: 0 | M25: Pas de sel d'Epsom ni de HE / 26g Huile végétale amande douce = 2 c. à table / 13g Beurre de karité fondu = 1 c. à table | P25: public
A26: PRO-001 | B26: COL-004 | C26: GAM-006 | E26: BAISER FRUITÉ | F26: Ferme les yeux et laisse-toi porter par les vergers en fleurs ! Fraise et cerise se mêlent en un duo gourmand et envoûtant. Un baume qui hydrate, protège et donne envie d'être embrassée. | G26: La douceur des fruits rouges, un brillant qui fait tout dire. | H26: #5A1C37 | I26: 0 | J26: 18 | K26: 0 | M26: Colore les lèvres / 2-4g Allantoine selon sensibilité | P26: public
A27: PRO-002 | B27: COL-004 | C27: GAM-006 | E27: NUAGE FRAISE | F27: Les petites lèvres méritent les meilleurs soins. Nuage Fraise est formulé sans huile essentielle, sans mica, avec des ingrédients doux et non toxiques pensés pour les tout-petits. | G27: Doux comme un nuage, sucré comme une fraise — un baume sécuritaire pour les petites lèvres. | H27: #9C1E45 | I27: 0 | J27: 18 | K27: 0 | M27: Zéro HE, Zéro Mica, Comestibles et non toxiques | P27: public
A28: PRO-003 | B28: COL-004 | C28: GAM-006 | E28: PETIT NUAGE DOUILLET | F28: L'hiver est rude, même pour les plus petits. Petit Nuage Douillet est une version hivernale plus enveloppante, avec davantage de cire d'abeille et de karité pour protéger les lèvres fragilisées par le froid. | G28: Un câlin pour les petites lèvres quand le froid arrive — doux, sécuritaire et réconfortant. | H28: #519A9C | J28: 18 | K28: 0 | M28: Zéro HE, Zéro Mica, Comestibles et non toxiques | P28: public | Q28: COL-002
A29: PRO-050 | B29: COL-004 | C29: GAM-006 | E29: FRAISE ET BASILIC | F29: Qui aurait pensé marier la fraise et le basilic ? La douceur sucrée de la fraise rencontre le caractère herbacé du basilic pour créer quelque chose d'unique et d'inoubliable. | G29: L'audace d'un duo inattendu, la douceur d'un instant gourmand. | H29: #B60F31 | I29: 0 | J29: 18 | K29: 0 | M29: 5g Vitamine E = 1 c. à thé / 10g Sirop de fraise = 2 c. à thé | P29: public
A30: PRO-055 | B30: COL-004 | C30: GAM-006 | E30: LAVANDE - ROMARIN | F30: Fermez les yeux et respirez. La lavande apaise, le romarin vivifie. Ensemble ils forment un duo intemporel qui nourrit les lèvres en profondeur. | G30: La sérénité de la lavande, la vigueur du romarin. La Provence dans un baume. | H30: #908ED3 | I30: 0 | J30: 18 | K30: 0 | M30: 100% naturel, 100% essentiel | P30: public
A31: PRO-057 | B31: COL-004 | C31: GAM-006 | E31: MENTHE POIVRÉE | F31: Vive, pétillante et sans compromis, menthe poivrée réveille les lèvres et les sens d'un seul geste. | G31: Un frisson de fraîcheur, même en plein hiver. | H31: #90FAD3 | I31: 0 | J31: 18 | K31: 0 | M31: 5g Vitamine E = 1 c. à thé / 5g arôme naturel de menthe poivrée = 1 c. à thé / Vérifier nom — Menthe poivrée ou Frisson de menthe ? | P31: public
A32: PRO-075 | B32: COL-004 | C32: GAM-006 | E32: SOUFFLE D'ÉTÉ | F32: Quand le soleil brûle et dessèche, Souffle d'été prend soin de tes lèvres avec douceur. Un baume réparateur et nacré, enrichi en karité, calendula et allantoine. | G32: Un souffle de fraîcheur pour des lèvres réparées par le soleil. | H32: #F1FFBB | I32: 0 | J32: 18 | K32: 0 | M32: Nacré blanc sans trop. | P32: public
A33: PRO-076 | B33: COL-004 | C33: GAM-006 | E33: SOUFFLE D'HIVER | F33: Quand le froid mord et que l'air se fait lourd, Souffle d'hiver veille. Ses vapeurs d'eucalyptus, de menthe et de ravintsara dégagent les narines et apaisent les lèvres gercées. | G33: Un souffle chaud qui libère, répare et protège au cœur de l'hiver. | J33: 18 | K33: 0 | M33: 5 gouttes colorant bleu | P33: public
A34: PRO-077 | B34: COL-004 | C34: GAM-006 | E34: VENT FRAIS | F34: Inspiré des grands espaces et des matins clairs. Vent frais est un baume sans artifice, pour elle comme pour lui. Menthe, eucalyptus et tea tree se fondent en une sensation de fraîcheur immédiate. | G34: La nature à l'état pur, sur tes lèvres. | H34: #609C6A | I34: 0 | J34: 18 | K34: 0 | M34: Déconseillé aux femmes enceintes et enfants de moins de 6 ans | P34: public
A35: PRO-021 | B35: COL-004 | C35: GAM-008 | E35: BRUME DE ROSÉE | F35: Comme une promenade matinale après la pluie, ce savon exfoliant capture la fraîcheur de l'aube. | G35: Le luffa réveille, la menthe vivifie. Une fraîcheur verte pour une peau neuve. | H35: #9EBD7C | I35: 0 | J35: 9 | K35: 28 | M35: Micas à fleurs bleues ⚠️ quantité à confirmer / Couleur vert grass / 9 Luffa (1 par savon) | P35: public
A36: PRO-051 | B36: COL-005 | C36: GAM-009 | E36: GRAIN D'ACIER | F36: Les mains qui travaillent méritent un savon à leur mesure. Grain d'acier nettoie en profondeur sans agresser, la pierre ponce retire les salissures tenaces. | G36: Un savon robuste et épuré, conçu pour les mains marquées d'huile et de métal. Sa mousse dense décroche la graisse et laisse la peau nette. | H36: #545454 | I36: 0.05 | J36: 10 | K36: 42 | M36: 7g Pierre ponce = 2 c. à thé / 3.5g Argile blanche = 1 c. à thé / Savon gris pâle avec mouchette de charbon activé végétal pour rappeler le métal. | N36: https://res.cloudinary.com/dfasrauyy/image/upload/v1773085030/univers-caresse/produits/dgskttwylxoqxh1x689n.jpg | P36: public | Q36: LUI
A37: PRO-052 | B37: COL-005 | C37: GAM-009 | E37: HERBE DOUCE | F37: Il y a des savons qui ne font pas de bruit. Herbe douce est de ceux-là. Le pin blanc apporte sa fraîcheur résineuse, la poire sa douceur juteuse. | G37: Un savon clair et apaisant, où le pin blanc et la poire se mêlent à une lumière douce. Une fraîcheur verte, simple et pure, comme un matin tranquille. | H37: #425B00 | I37: 0 | J37: 10 | K37: 42 | M37: 3.5g Argile blanche = 1 c. à thé / Vert sauge dans une petite quantité de pâte, ajouté sans trop mêler | N37: https://res.cloudinary.com/dfasrauyy/image/upload/v1773085101/univers-caresse/produits/p0dsiibm02qrmhuluhok.jpg | P37: public
A38: PRO-058 | B38: COL-005 | C38: GAM-009 | E38: MOUSSE D'ESPRESSO | F38: Pour ceux qui commencent leur journée avec un café et la terminent avec un autre. Le marc de café exfolie en douceur, le cacao enveloppe d'une chaleur gourmande. | G38: Un parfum mocha, une mousse chaleureuse, des grains qui réveillent la peau. | H38: #3F2300 | I38: 0 | J38: 10 | K38: 42 | M38: 22g Marc de café = 2 c. à table / 11g Cacao en poudre = 1 c. à table | N38: https://res.cloudinary.com/dfasrauyy/image/upload/v1773085149/univers-caresse/produits/gewk6wpfn1tet13vzsnc.jpg | P38: public
A39: PRO-059 | B39: COL-005 | C39: GAM-009 | E39: MURMURE D'OLIVA | F39: L'huile d'olive vierge est l'ancêtre des savons. Ici, elle est à l'honneur, accompagnée du romarin et du citron qui lui donnent une vivacité méditerranéenne. | G39: Un souffle doux venu de la Méditerranée. | H39: #A2AF0E | I39: 0 | J39: 10 | K39: 42 | M39: 17.5g Argile verte = 5 c. à thé / 10g Romarin séché = 5 c. à thé / Verser moules en cubes avec une demie tranche de citron dans chaque cube | N39: https://res.cloudinary.com/dfasrauyy/image/upload/v1773085196/univers-caresse/produits/m5gjwtn5cfdctygdzawl.jpg | P39: public
A40: PRO-015 | B40: COL-006 | C40: GAM-010 | E40: BRISE MATINALE | F40: Ce shampoing solide Équilibra réveille la chevelure d'une fraîcheur délicate et enveloppante. | G40: Sous sa caresse, le cuir chevelu s'illumine comme au lever du jour. | H40: #6787FF | I40: 0 | J40: 1 | K40: 0 | M40: Ce savon est beige / 8-10 gouttes HE menthe poivrée | N40: https://res.cloudinary.com/dfasrauyy/image/upload/v1773084533/univers-caresse/produits/dk74oyfcggmp3qgcmhpl.png | P40: public
...

Sheet  Gammes_Ingredients_v2
A1: GAM-id | B1: ING-id | C1: nom_ingredient | D1: quantite_g
A2: GAM-1775518159265 | B2: ING-132 | C2: Saindoux | D2: 2500
A3: GAM-1775518159265 | B3: ING-004 | C3: Eau | D3: 1000
A4: GAM-1775518159265 | B4: ING-005 | C4: Soude caustique (NaOH) | D4: 340
A5: GAM-1775518159265 | B5: ING-051 | C5: HE sapin | D5: 40
A6: GAM-1775518159265 | B6: ING-014 | C6: Argile blanche | D6: 15
A7: GAM-1775518159265 | B7: ING-133 | C7: Sel | D7: 15
A8: GAM-001 | B8: ING-002 | C8: Huile de tournesol oléique | D8: 325
A9: GAM-001 | B9: ING-006 | C9: Huile de coco | D9: 260
A10: GAM-001 | B10: ING-004 | C10: Eau | D10: 184
A11: GAM-001 | B11: ING-005 | C11: Soude caustique (NaOH) | D11: 92
A12: GAM-001 | B12: ING-003 | C12: Beurre de karité | D12: 65
A13: GAM-002 | B13: ING-001 | C13: Huile d'olive | D13: 250
... A23: GAM-003 | B23: ING-005 | C23: Soude caustique (NaOH) | D23: 98
F24: GAM-004
F25: GAM-005
F26: GAM-006
F27: GAM-007
F28: GAM-008
F29: GAM-009
F30: GAM-010
F31: GAM-011
F32: GAM-012
F33: GAM-013
F34: GAM-014
F35: GAM-015
... F41: GAM-1775518159265

Sheet Produits_Formats_v2
A1: PRO-id | B1: poids | C1: unite | D1: prix_vente | E1: EMB-id
A2: PRO-028 | B2: 72 | C2: g | D2: 7 | G2: =VLOOKUP(A2,Produits_v2!A:C,2,FALSE) -> COL-003 | H2: =VLOOKUP(G2,Collections_v2!A:C,2,FALSE) -> 3 | I2: =VLOOKUP(G2,Collections_v2!A:C,3,FALSE) -> CAPRIN | J2: =VLOOKUP(A2,Produits_v2!A:E,5,FALSE) -> CAPRICE FRAISÉ
A3: PRO-029 | B3: 72 | C3: g | D3: 7 | G3: =VLOOKUP(A3,Produits_v2!A:C,2,FALSE) -> COL-003 | H3: =VLOOKUP(G3,Collections_v2!A:C,2,FALSE) -> 3 | I3: =VLOOKUP(G3,Collections_v2!A:C,3,FALSE) -> CAPRIN | J3: =VLOOKUP(A3,Produits_v2!A:E,5,FALSE) -> CERISE DE VELOURS
A4: PRO-042 | B4: 90 | C4: g | D4: 7 | G4: =VLOOKUP(A4,Produits_v2!A:C,2,FALSE) -> COL-001 | H4: =VLOOKUP(G4,Collections_v2!A:C,2,FALSE) -> 1 | I4: =VLOOKUP(G4,Collections_v2!A:C,3,FALSE) -> SAPONICA | J4: =VLOOKUP(A4,Produits_v2!A:E,5,FALSE) -> ÉCLAT TROPICAL
A5: PRO-043 | B5: 72 | C5: g | D5: 7 | G5: =VLOOKUP(A5,Produits_v2!A:C,2,FALSE) -> COL-003 | H5: =VLOOKUP(G5,Collections_v2!A:C,2,FALSE) -> 3 | I5: =VLOOKUP(G5,Collections_v2!A:C,3,FALSE) -> CAPRIN | J5: =VLOOKUP(A5,Produits_v2!A:E,5,FALSE) -> ÉCLOSION DE SOIE
A6: PRO-052 | B6: 125 | C6: g | D6: 7 | G6: =VLOOKUP(A6,Produits_v2!A:C,2,FALSE) -> COL-005 | H6: =VLOOKUP(G6,Collections_v2!A:C,2,FALSE) -> 5 | I6: =VLOOKUP(G6,Collections_v2!A:C,3,FALSE) -> ÉPURE | J6: =VLOOKUP(A6,Produits_v2!A:E,5,FALSE) -> HERBE DOUCE
A7: PRO-079 | B7: 330 | C7: g | D7: 30 | G7: =VLOOKUP(A7,Produits_v2!A:C,2,FALSE) -> COL-008 | H7: =VLOOKUP(G7,Collections_v2!A:C,2,FALSE) -> 8 | I7: =VLOOKUP(G7,Collections_v2!A:C,3,FALSE) -> LUI | J7: =VLOOKUP(A7,Produits_v2!A:E,5,FALSE) -> L'INSTANT DU BARBIER
A8: PRO-079 | B8: 200 | C8: g | D8: 20 | G8: =VLOOKUP(A8,Produits_v2!A:C,2,FALSE) -> COL-008 | H8: =VLOOKUP(G8,Collections_v2!A:C,2,FALSE) -> 8 | I8: =VLOOKUP(G8,Collections_v2!A:C,3,FALSE) -> LUI | J8: =VLOOKUP(A8,Produits_v2!A:E,5,FALSE) -> L'INSTANT DU BARBIER
A9: PRO-058 | B9: 125 | C9: g | D9: 7 | G9: =VLOOKUP(A9,Produits_v2!A:C,2,FALSE) -> COL-005 | H9: =VLOOKUP(G9,Collections_v2!A:C,2,FALSE) -> 5 | I9: =VLOOKUP(G9,Collections_v2!A:C,3,FALSE) -> ÉPURE | J9: =VLOOKUP(A9,Produits_v2!A:E,5,FALSE) -> MOUSSE D'ESPRESSO
A10: PRO-059 | B10: 125 | C10: g | D10: 7 | G10: =VLOOKUP(A10,Produits_v2!A:C,2,FALSE) -> COL-005 | H10: =VLOOKUP(G10,Collections_v2!A:C,2,FALSE) -> 5 | I10: =VLOOKUP(G10,Collections_v2!A:C,3,FALSE) -> ÉPURE | J10: =VLOOKUP(A10,Produits_v2!A:E,5,FALSE) -> MURMURE D'OLIVA
A11: PRO-062 | B11: 72 | C11: g | D11: 7 | G11: =VLOOKUP(A11,Produits_v2!A:C,2,FALSE) -> COL-003 | H11: =VLOOKUP(G11,Collections_v2!A:C,2,FALSE) -> 3 | I11: =VLOOKUP(G11,Collections_v2!A:C,3,FALSE) -> CAPRIN | J11: =VLOOKUP(A11,Produits_v2!A:E,5,FALSE) -> ORANGE SAUVAGE
A12: PRO-063 | B12: 125 | C12: g | D12: 7 | G12: =VLOOKUP(A12,Produits_v2!A:C,2,FALSE) -> COL-009 | H12: =VLOOKUP(G12,Collections_v2!A:C,2,FALSE) -> 9 | I12: =VLOOKUP(G12,Collections_v2!A:C,3,FALSE) -> ANIMA | J12: =VLOOKUP(A12,Produits_v2!A:E,5,FALSE) -> PATTES BLANCHES
A13: PRO-070 | B13: 72 | C13: g | D13: 7 | G13: =VLOOKUP(A13,Produits_v2!A:C,2,FALSE) -> COL-003 | H13: =VLOOKUP(G13,Collections_v2!A:C,2,FALSE) -> 3 | I13: =VLOOKUP(G13,Collections_v2!A:C,3,FALSE) -> CAPRIN | J13: =VLOOKUP(A13,Produits_v2!A:E,5,FALSE) -> POMME D'ÉMERAUDE
... A36: PRO-049 | B36: 72 | C36: g | D36: 7 | G36: =VLOOKUP(A36,Produits_v2!A:C,2,FALSE) -> COL-003 | H36: =VLOOKUP(G36,Collections_v2!A:C,2,FALSE) -> 3 | I36: =VLOOKUP(G36,Collections_v2!A:C,3,FALSE) -> CAPRIN | J36: =VLOOKUP(A36,Produits_v2!A:E,5,FALSE) -> FRAÎCHEUR DE MELON
A37: PRO-074 | B37: 125 | C37: g | D37: 7
A38: PRO-004 | B38: 90 | C38: g | D38: 7
A39: PRO-032 | B39: 90 | C39: g | D39: 7
A40: PRO-033 | B40: 90 | C40: g | D40: 7
A41: PRO-040 | B41: 90 | C41: g | D41: 7
A42: PRO-047 | B42: 90 | C42: g | D42: 7
A43: PRO-048 | B43: 90 | C43: g | D43: 7
A44: PRO-054 | B44: 90 | C44: g | D44: 7
A45: PRO-061 | B45: 90 | C45: g | D45: 7
A46: PRO-065 | B46: 75 | C46: g | D46: 5
A47: PRO-034 | B47: 90 | C47: g | D47: 10
A48: PRO-013 | B48: 90 | C48: g | D48: 10
... A52: PRO-039 | B52: 200 | C52: g | D52: 15
A53: PRO-038 | B53: 500 | C53: ml
A54: PRO-035 | B54: 500 | C54: ml | D54: 0
A55: PRO-036 | B55: 500 | C55: ml | D55: 0
A56: PRO-037 | B56: 500 | C56: ml | D56: 0
A57: PRO-019 | B57: 500 | C57: ml
A58: PRO-022 | B58: 10 | C58: g | D58: 1
A59: PRO-022 | B59: 135 | C59: g | D59: 8
A60: PRO-022 | B60: 240 | C60: g | D60: 15
A61: PRO-023 | B61: 10 | C61: g | D61: 1
A62: PRO-023 | B62: 135 | C62: g | D62: 8
A63: PRO-023 | B63: 240 | C63: g | D63: 15
A64: PRO-012 | B64: 90 | C64: g | D64: 7
A65: PRO-031 | B65: 90 | C65: g | D65: 7
...

Sheet Produits_Ingredients_v2
A1: PRO-id | B1: ING-id | C1: nom_ingredient | D1: quantite_g
A2: PRO-001 | B2: ING-107 | C2: Allantoine | D2: 4
A3: PRO-001 | B3: ING-098 | C3: Arôme cerise | D3: 0.6
A4: PRO-001 | B4: ING-089 | C4: Arôme de fraises | D4: 0.6
A5: PRO-001 | B5: ING-003 | C5: Beurre de karité | D5: 30
A6: PRO-001 | B6: ING-013 | C6: Beurre de mangue | D6: 14
A7: PRO-001 | B7: ING-091 | C7: Cire de carnauba | D7: 20
A8: PRO-001 | B8: ING-080 | C8: Huile de calendula | D8: 25
A9: PRO-001 | B9: ING-010 | C9: Huile végétale jojoba | D9: 25
A10: PRO-001 | B10: ING-104 | C10: Mica rose-rouge | D10: 1.5
A11: PRO-001 | B11: ING-092 | C11: Vitamine E | D11: 1.5
A12: PRO-002 | B12: ING-089 | C12: Arôme de fraises | D12: 0.5
A13: PRO-002 | B13: ING-003 | C13: Beurre de karité | D13: 30
... A578: PRO-030 | B578: ING-130 | C578: Poudre ortie | D578: 5

Sheet Emballages_v2
A1: EMB-id | B1: nom | C1: type

Sheet Lots_v2
A1: LOT-id | B1: PRO-id | C1: multiplicateur | D1: nb_unites | E1: date_fabrication | F1: date_disponibilite | G1: cout_ingredients | H1: cout_emballages | I1: cout_revient_total | J1: cout_par_unite | K1: statut | L1: format_poids | M1: format_unite
A2: LOT-1775524552326 | B2: PRO-048 | C2: 1 | D2: 1 | E2: 46023 | F2: 46051 | G2: 0 | H2: 0 | I2: 0 | J2: 0 | K2: en_cure | L2: 95 | M2: g

Sheet Ingredients_INCI_v2
A1: ING-id | B1: CAT-id | C1: nom_fournisseur | D1: nom_UC | E1: INCI | F1: nom_botanique | G1: source | H1: note_olfactive | I1: statut | J1: date_ajout
A2: ING-001 | B2: CAT-007 | C2: Huile végétale Olive | D2: Huile d'olive | E2: Olea europaea oil | G2: PA | I2: ✅ Validé | J2: 46109
A3: ING-002 | B3: CAT-007 | C3: Huile végétale Tournesol | D3: Huile de tournesol oléique | E3: Helianthus Annuus (Sunflower) Seed Oil (High Oleic, 80%) | G3: PA | I3: ✅ Validé | J3: 46109
A4: ING-003 | B4: CAT-002 | C4: Beurre Karité | D4: Beurre de karité | E4: Butyrospermum parkii (Shea) Butter | G4: PA | I4: ✅ Validé | J4: 46109
A5: ING-004 | B5: CAT-011 | C5: Eau | D5: Eau | E5: Aqua | G5: PA | I5: ✅ Validé | J5: 46109
A6: ING-005 | B6: CAT-012 | C6: Soude Caustique (NaOH) | D6: Soude caustique (NaOH) | E6: Sodium Hydroxide | G6: PA | I6: ✅ Validé | J6: 46112
A7: ING-006 | B7: CAT-007 | C7: Huile végétale Noix de Coco | D7: Huile de coco | E7: Cocos nucifera (Coconut) Oil | G7: PA | I7: ✅ Validé | J7: 46111
A8: ING-007 | B8: CAT-007 | C8: Huile végétale Amande douce | D8: Huile végétale amande douce | E8: Prunus amygdalus | G8: PA | I8: ✅ Validé | J8: 46109
A9: ING-008 | B9: CAT-007 | C9: Huile végétale Ricin | D9: Huile de ricin | E9: Ricinus Communis (Castor) Seed Oil | G9: PA | I9: ✅ Validé | J9: 46109
A10: ING-009 | B10: CAT-007 | C10: Huile végétale Argan | D10: Huile d'argan | E10: Argania spinosa | G10: PA | I10: ✅ Validé | J10: 46109
A11: ING-010 | B11: CAT-007 | C11: Huile végétale Jojoba | D11: Huile végétale jojoba | E11: Simmondsia Sinensis | G11: PA | I11: ✅ Validé | J11: 46109
A12: ING-011 | B12: CAT-007 | C12: Huile végétale Pépins de raisin | D12: Huile végétale de pépins de raisin | E12: Vitis vinifera (grape) seed oil | G12: PA | I12: ✅ Validé | J12: 46109
A13: ING-012 | B13: CAT-002 | C13: Beurre de Cacao brut | D13: Beurre de cacao brut | E13: Theobroma cacao (Cocoa) Seed Butter | G13: PA | I13: ✅ Validé | J13: 46109
A14: ING-013 | B14: CAT-002 | C14: Beurre de mangue | D14: Beurre de mangue | E14: Mangifera indica seed butter | F14: Mangifera indica | G14: MH | I14: ✅ Validé | J14: 46109
A15: ING-014 | B15: CAT-001 | C15: Argile blanche (Kaolin) | D15: Argile blanche | E15: Kaolin (Bolus Alba) | G15: PA | I15: ✅ Validé | J15: 46109
A16: ING-015 | B16: CAT-001 | C16: Argile rose | D16: Argile rose | E16: Kaolin (Bolus Alba) / Illite (Bolus Alba) | G16: PA | I16: ✅ Validé | J16: 46109
A17: ING-016 | B17: CAT-001 | C17: Argile rouge | D17: Argile rouge | E17: Illite red clay | G17: PA | I17: ✅ Validé | J17: 46109
A18: ING-017 | B18: CAT-001 | C18: Argile multani mitti | D18: Argile Multani mutti | E18: Solum fullonum | G18: PA | I18: ✅ Validé | J18: 46109
A19: ING-018 | B19: CAT-004 | C19: Charbon activé végétal | D19: Charbon activé végétal | E19: Activated charcoal | G19: PA | I19: ✅ Validé | J19: 46109
A20: ING-019 | B20: CAT-005 | C20: Smoothie aux mûres fragrance | D20: Smoothie aux mûres (fragrance) | E20: Fragrance | G20: PA | I20: ✅ Validé | J20: 46109
A21: ING-020 | B21: CAT-005 | C21: Gomme balloune fragrance | D21: Gomme balloune (fragrance) | E21: Fragrance | G21: PA | I21: ✅ Validé | J21: 46109
A22: ING-021 | B22: CAT-005 | C22: Poudre de bébé fragrance | D22: Fragrance poudre de bébé | E22: Fragrance | G22: PA | I22: ✅ Validé | J22: 46109
A23: ING-022 | B23: CAT-001 | C23: Argile verte | D23: Argile verte | E23: Montmorillonite | G23: MH | I23: ✅ Validé | J23: 46109
A24: ING-023 | B24: CAT-008 | C24: Huile aromatique O Masculin | D24: HA O'masculin | E24: Cedrus Atlantica (Atlas Cedar) Wood Oil; Jasminum Grandiflorum (Jasmine) Flower Oil; Michelia Alba (Magnolia) Flower Oil; Pogostemon Cablin (Patchouli) Leaf Oil; Rosmarinus Officinalis (Rosemary) Leaf Oil | G24: PA | I24: ✅ Validé | J24: 46109
A25: ING-024 | B25: CAT-012 | C25: Sodium cocoyl isethionate (SCI) | D25: SCI | E25: Sodium cocoyl isethionate | G25: MH | I25: ✅ Validé | J25: 46112
A26: ING-025 | B26: CAT-006 | C26: Fleurs de lavande | D26: Fleurs de lavande | E26: Lavandula angustifolia (lavender) flower | G26: PA | I26: ✅ Validé | J26: 46109
A27: ING-026 | B27: CAT-006 | C27: Pétales de roses | D27: Pétales de roses | E27: Rosa × damascena Flower Powder | F27: Rosa ×damascena | G27: PA | I27: ✅ Validé | J27: 46109
A28: ING-027 | B28: CAT-003 | C28: Cire de Soja | D28: Cire de soya | E28: Soy wax | G28: PA | I28: ✅ Validé | J28: 46109
A29: ING-028 | B29: CAT-012 | C29: Sel d'Epsom | D29: Sel d'Epsom | E29: Magnesium sulfate | G29: MH | I29: ✅ Validé | J29: 46109
A30: ING-029 | B30: CAT-010 | C30: Hydrolat Romarin | D30: Hydrolat romarin | E30: Rosmarinus officinalis Leaf Water | G30: PA | I30: ✅ Validé | J30: 46109
A31: ING-030 | B31: CAT-010 | C31: Hydrolat Lavande | D31: Hydrolat lavande | E31: Lavandula angustifolia (Lavender) Flower Water | G31: PA | I31: ✅ Validé | J31: 46109
A32: ING-031 | B32: CAT-010 | C32: Hydrolat Menthe Poivrée | D32: Hydrolat de menthe poivrée | E32: Mentha piperita (Peppermint) Leaf Water | G32: PA | I32: ✅ Validé | J32: 46109
A33: ING-032 | B33: CAT-006 | C33: Shikakai en poudre | D33: Shikakaï en poudre | E33: Acacia concinna Fruit Powder | G33: PA | I33: ✅ Validé | J33: 46109
A34: ING-033 | B34: CAT-006 | C34: Racine de guimauve en poudre | D34: Poudre de guimauve | E34: Althaea officinalis Root Powder | G34: PA | I34: ✅ Validé | J34: 46109
A35: ING-034 | B35: CAT-006 | C35: Poudre d'orange | D35: Poudre écorce orange | E35: Citrus sinensis | G35: PA | I35: ✅ Validé | J35: 46109
A36: ING-035 | B36: CAT-009 | C36: Huile essentielle Petitgrain bigarade | D36: HE petitgrain | E36: Citrus Aurantium ssp. aurantium (Petitgrain Bigarade) Leaf Oil | F36: Citrus aurantium ssp aurantium | G36: PA | I36: ✅ Validé | J36: 46109
A37: ING-036 | B37: CAT-009 | C37: Huile essentielle Cèdre feuilles | D37: HE cèdre feuilles | E37: thuja occidentalis leaf oil | G37: PA | I37: ✅ Validé | J37: 46109
A38: ING-037 | B38: CAT-009 | C38: Huile essentielle Cèdre atlas | D38: HE cèdre atlas | E38: cedrus atlantica bark oil | G38: PA | I38: ✅ Validé | J38: 46109
A39: ING-038 | B39: CAT-009 | C39: Huile essentielle Palmarosa | D39: HE palmarosa | E39: Cymbopogon Martini (Palmarosa) Oil | F39: Cymbopogon martinii var motia | G39: PA | I39: ✅ Validé | J39: 46109
A40: ING-039 | B40: CAT-009 | C40: Huile essentielle Lavande vraie | D40: HE lavande | E40: lavandula angustifolia (lavender) oil | G40: PA | I40: ✅ Validé | J40: 46109
...

Sheet Scraping_PA_v2
A1: Fournisseur | B1: Nom | C1: Catégorie | D1: INCI | E1: Nom_botanique | F1: Partie_plante | G1: Origine | H1: Methode_production | I1: Chemotype | J1: Culture | K1: Composantes_majoritaires | L1: Point_eclair | M1: Bio | N1: Odeur | O1: NPN | P1: Marque | Q1: URL | R1: Qualite | S1: Statut | T1: Date_scraping | U1: Texte_brut
A2: Pure Arôme | B2: Argile bentonite | C2: Argiles | D2: Sodium bentonite | Q2: https://www.purearome.com/fr/produit/argile-bentonite | T2: 46108
A3: Pure Arôme | B3: Argile blanche (Kaolin) | C3: Argiles | D3: Kaolin (Bolus Alba | Q3: https://www.purearome.com/fr/produit/argile-blanche-kaolin | R3: Propre | T3: 46108 | U3: Argile Kaolin Accueil Produits Argiles Argile blanche (Kaolin) Argile blanche (Kaolin) Sku: KAOLIN En stock Argile blanche (Kaolin) Sku: KAOLIN En stock 5,95 $ CAD Produit non disponible à l'achat en ligne Partager Argile blanche Kaolin Inci : Kaolin (Bolus Alba) CAS : 1332-58-7 Kaolin aussi appelée argile blanche, est naturellement riche en sels minéraux (fer, zinc, silicium, magnésium, potassium, calcium…). Réputée apaisante et purifiante, elle est idéale pour les peaux sèches, irritées et fragiles pour dégonfler la peau et apaiser le feu cutané. Utilisée en masque ou en cataplasme, elle convient parfaitement pour les petits bobos et les irritations. Elle est aussi reconnue pour adoucir la peau ou bien même renforcer les cheveux secs, ont l'emploi également dans la fabrication de savon et shampoing. Pour usage externe seulement
A4: Pure Arôme | B4: Argile ghassoul / rhassoul | C4: Argiles | D4: Marroccan lava clay | Q4: https://www.purearome.com/fr/produit/argile-ghassoul-rhassoul | R4: Propre | T4: 46108 | U4: Argile Ghassoul / Rhassoul Accueil Produits Argiles Argile ghassoul / rhassoul Argile ghassoul / rhassoul Sku: ARGHAS En stock Argile ghassoul / rhassoul Sku: ARGHAS En stock 8,50 $ CAD Produit non disponible à l'achat en ligne Partager Argile Rhassoul du Maroc (Ghassoul) Inci : Marroccan lava clay CAS : 12417-86-6 Véritable &quot;terre qui lave&quot;, le Rhassoul est une argile volcanique récoltée dans la région du Moyen Atlas au Maroc. Il s'utilise pour préparer des shampooings en pâte doux et purifiants grâce à son aptitude exceptionnelle à absorber les impuretés sans irriter la peau. C'est un élément incontournable des rituels du hammam. A la différence des shampooings et savons, le Rhassoul ne contient aucun tensioactif et nettoie selon un processus physique en absorbant les impuretés et les graisses. Il respecte ainsi le film hydrolipidique de la peau et du cheveu et n'irrite pas les glandes sébacées.
A5: Pure Arôme | B5: Argile multani mitti | C5: Argiles | D5: Solum fullonum | Q5: https://www.purearome.com/fr/produit/argile-multani-mitti | R5: Propre | T5: 46108 | U5: Argile Multani Mitti Accueil Produits Argiles Argile multani mitti Argile multani mitti Sku: MULTANI En stock Argile multani mitti Sku: MULTANI En stock 6,50 $ CAD Produit non disponible à l'achat en ligne Partager Argile Multani Mitti Inci : Solum fullonum CAS : 8031-18-3 Cette argile indienne s'utilise en association avec des poudres de plantes pour nettoyer et purifier la peau et les cheveux. Elle fait merveille notamment pour préparer des masques aux poudres ayurvédiques, ou des shampooing pâte "no poo". Particulièrement appréciée par les peaux et cheveux gras, elle élimine en douceur les impuretés et cellules mortes. Elle est aussi connue sous le nom de terre à foulon et peut s'utiliser comme produit ménager écologique pour absorber les taches de gras ou préparer une "pierre d'argile".
A6: Pure Arôme | B6: Argile rose | C6: Argiles | D6: Kaolin (Bolus Alba) / Illite (Bolus Alba) | Q6: https://www.purearome.com/fr/produit/argile-rose | R6: Propre | T6: 46108 | U6: Argile Rose Accueil Produits Argiles Argile rose Argile rose Sku: ARGROSE En stock Argile rose Sku: ARGROSE En stock 8,50 $ CAD Produit non disponible à l'achat en ligne Partager Argile Rose INCI : Kaolin (Bolus Alba) / Illite (Bolus Alba) CAS : 1332-58-7 L'argile Rose Pure arôme est reconnus pour adoucir la peau et renforce les cheveux secs, ont l'emploi également dans la fabrication de savon et shampoing. Apaisante et purifiante, elle est idéale pour les peaux sèches, irritées et fragiles pour dégonfler la peau et apaiser le feu cutané. Utilisée en masque ou en cataplasme, elle convient parfaitement pour les petits bobos et les irritations.
A7: Pure Arôme | B7: Argile rouge | C7: Argiles | D7: Illite red clay | Q7: https://www.purearome.com/fr/produit/argile-rouge | R7: Propre | T7: 46108 | U7: Argile Rouge Accueil Produits Argiles Argile rouge Argile rouge Sku: ARGROU En stock Argile rouge Sku: ARGROU En stock 11,50 $ CAD Produit non disponible à l'achat en ligne Partager Argile Rouge Inci : Illite red clay CAS : 12173-60-3 L'argile rouge est riche en oxyde de fer et en oligo-éléments. Elle fait partie de la famille des illites. L'argile illite rouge minéralise la peau et est idéale pour tout les types de peaux. Elle est idéale pour préparer des masques, cataplasmes, et enveloppements. Cette argile est un indispensable !
A8: Pure Arôme | B8: Argile verte surfine montmorillonite | C8: Argiles | D8: Illite (Bolus Alba | Q8: https://www.purearome.com/fr/produit/argile-verte-surfine-montmorillonite | R8: Propre | T8: 46108 | U8: Argile verte Surfine Montmorillonite Accueil Produits Argiles Argile verte surfine montmorillonite Argile verte surfine montmorillonite Sku: ARVERT En stock Argile verte surfine montmorillonite Sku: ARVERT En stock 9,99 $ CAD Produit non disponible à l'achat en ligne Partager Argile Verte Surfine Montmorillonite Inci : Illite (Bolus Alba) CAS : 1318-93-0 L'argile verte montmorillonite est connue depuis des centaines d'années ; son nom vient de la localité de Montmorillon, dans la Vienne. Notre argile montmorillonite verte surfine est extraite de carrières françaises. Riche en sels minéraux et oligo-éléments et dotée d'une forte capacité d'adsorption, cette argile a des vertus purifiantes sur la peau. Elle s'utilise à merveille pour préparer des soins nettoyants des peaux grasses ou à imperfections et des cuirs chevelus gras ou squameux.
A9: Pure Arôme | B9: Base Beurre de bain moussant | C9: Bases neutres | D9: Glycerin, Aqua, Sorbitol, Sodium Cocoyl Isethionate, Sodium Lauryl Sulfoacetate, Sodium Chloride, Phenoxyethanol, Ethylhexylglycerin. | Q9: https://www.purearome.com/fr/produit/base-beurre-de-bain-moussant | R9: Base | T9: 46108 | U9: Base Beurre de bain moussant Accueil Produits Base Beurre de bain moussant Base Beurre de bain moussant Sku: BEUBMOUSS En stock Base Beurre de bain moussant Sku: BEUBMOUSS En stock 32,95 $ CAD Produit non disponible à l'achat en ligne Partager Base Beurre de Bain Moussant Sans Parabènes et Sans Propylène Glycol Une belle alternative créative pour des bains luxueux Découvrez notre Beurre de Bain Moussant, une base unique et polyvalente pour vos créations cosmétiques. Idéale pour remplacer les bains moussants liquides ou en gel, cette base vous permet de réaliser des textures onctueuses, comme des beurres meringués, avec toutes les fantaisies de couleurs et de confettis que vous pouvez imaginer. Laissez libre cours à votre créativité et créez des produits de bain personnalisés et ludiques ! Caractéristiques : Sans parabènes et sans propylène glycol : Une composition douce pour la peau et respectueuse de l’environnement. Base non parfumée : Ajoutez vos propres arômes pour une expérience sensorielle unique et sur mesure. Texture crémeuse et moussante : Se transforme en une mousse riche et douce, parfaite pour un moment de relaxation au bain Conseils de Création : Cette base est conçue pour être parfumée selon vos préférences. Nous recommandons un dosage d’arôme entre **1 % et 2 % maximum** pour conserver la sécurité et l’intégrité du produit. Pour une touche spéciale, ajoutez des huiles essentielles / fragrances de votre choix. Que vous soyez un entrepreneur en cosmétique naturelle ou un passionné des soins faits maison, cette base Beurre de Bain Moussant apportera une touche luxueuse et créative à votre collection. Ingrédients : Glycerin, Aqua, Sorbitol, Sodium Cocoyl Isethionate, Sodium Lauryl Sulfoacetate, Sodium Chloride, Phenoxyethanol, Ethylhexylglycerin. Fabriqué au Canada Mise en Garde et Conformité : Avant de commercialiser votre produit fini, assurez-vous de respecter toutes les réglementations en vigueur et de soumettre le formulaire de déclaration des cosmétiques requis par Santé Canada. La conformité réglementaire est de votre responsabilité. . **Usage externe uniquement** : Ce produit est destiné à une utilisation externe. Document : Fiche Technique Base Beurre de bain moussant Pure arome Laboratoire.pdf
A10: Pure Arôme | B10: Base crème épaisse – Neutre | C10: Bases neutres | Q10: https://www.purearome.com/fr/produit/base-creme-epaisse-neutre | R10: À valider | T10: 46108 | U10: Base crème épaisse professionnelle – neutre prête à l’emploi Accueil Produits Base crème épaisse – Neutre Base crème épaisse – Neutre Sku: BCREME En stock Base crème épaisse – Neutre Sku: BCREME En stock 32,95 $ CAD Produit non disponible à l'achat en ligne Partager Base crème épaisse – Neutre Cette base crème épaisse est une base cosmétique professionnelle, hautement polyvalente et conçue pour être entièrement personnalisée. Sa texture riche, stable et homogène permet de créer une grande variété de produits : crème mains, crème corporelle, lotion fluide, gel-crème visage, soin parfumé, base massage, et bien plus. Elle ne doit pas être utilisée telle quelle. La base est intentionnellement concentrée pour permettre au client d’ajouter entre 5 à 75 % d’eau distillée selon la texture désirée. Vous pouvez la fluidifier, l’alléger, la doubler en volume ou la rendre encore plus riche selon vos besoins. Formulation douce, hydratante et stable, sans TEA, sans SLS, sans SLES, sans alcool , parfaitement compatible avec les huiles, fragrances, huiles essentielles, actifs liposolubles et hydrosolubles. Ingrédients (formule améliorée) Aqua (Water), Helianthus annuus (Sunflower) Seed Oil, Cetearyl Alcohol, Polysorbate 60, Simmondsia chinensis (Jojoba) Seed Oil, Limnanthes alba (Meadowfoam) Seed Oil, Aloe Barbadensis Leaf Juice, Glycerin, Cetyl Alcohol, Stearic Acid, Palmitic Acid, Tocopherol, Glycine soja (Soybean) Oil, Ascorbic Acid, Potassium Sorbate, Iodopropynyl Butylcarbamate, Diazolidinyl Urea. Caractéristiques techniques Aspect : crème blanche, épaisse, homogène Odeur : neutre Viscosité : élevée (texture crème épaisse) Modulable : peut être diluée avec jusqu’à 75 % d’eau distillée Compatibilité : huiles, actifs, fragrances, HE Qualité : sans TEA, sans alcool, sans SLS/SLES, non testé sur les animaux Conservation : 15–25 °C, à l’abri de l’humidité Provenance : Canada Mode d’emploi NE PAS utiliser la base telle quelle (base concentrée). Ajouter 5 à 75 % d’eau distillée selon la texture désirée. Ajouter fragrances ou huiles essentielles (1–3 %). Ajouter actifs hydrosolubles ou liposolubles compatibles. Mélanger doucement pour éviter l’aération. Emballer dans un contenant propre et stérile. Recettes exemples Crème pour les mains (riche) Base crème épaisse : 80 % Huile végétale : 5 % Eau distillée : 14 % Fragrance : 1 % Crème corporelle (moyenne) Base crème épaisse : 65 % Eau distillée : 30 % Huile végétale : 3 % Fragrance : 1–2 % Lotion hydratante (légère – peut être doublée) Base crème épaisse : 40 % Eau distillée : 55 % Huile végétale : 3 % Fragrance : 1–2 % Gel-crème visage (léger & frais) Base crème épaisse : 45 % Eau distillée : 45 % Gel Aloe : 8 % Fragrance douce : 1–2 % Mise en garde Usage externe uniquement. Ne pas utiliser la base telle quelle sans transformation. Ne pas ingérer. Éviter le contact avec les yeux. Tenir hors de portée des enfants. Ne pas surchauffer la base. Toujours tester vos ajouts sur une petite quantité. Pure Arôme Laboratoire décline toute responsabilité en cas de mauvaise utilisation ou réaction liée au produit fini créé par le client. Mise en garde et conformité Avant de commercialiser votre produit fini, assurez-vous de respecter toutes les réglementations en vigueur et de soumettre la déclaration cosmétique requise par Santé Canada. La conformité demeure sous votre responsabilité. Note importante, mais tout en douceur Les informations partagées ici sont proposées avec rigueur et bienveillance, basées sur les données scientifiques et notre expérience. Elles ne remplacent pas un avis médical. Nous t’encourageons à réaliser des tests en petite quantité dans tes formules. Pure Arôme Laboratoire reste à tes côtés pour t’accompagner 💛. Document : Ingrédients % Base crème épaisse - neutre.pdf
